
Currently Loaded Modules:
  1) tools/miniconda/python3.8/4.9.2

 

WARNING: overwriting environment variables set in the machine
overwriting variable nnUNet_raw_data_base nnUNet_preprocessed RESULTS_FOLDER OUTPUT
  Running command git clone -q https://github.com/FabianIsensee/hiddenlayer.git /tmp/pip-install-f0t5n4di/hiddenlayer_f2f76b57500a40c69f11545262ed51f6
  Running command git checkout -b more_plotted_details --track origin/more_plotted_details
  Switched to a new branch 'more_plotted_details'
  Branch 'more_plotted_details' set up to track remote branch 'more_plotted_details' from 'origin'.
Traceback (most recent call last):
  File "/home/smaijer/.conda/envs/nn/bin/nnUNet_train", line 33, in <module>
    sys.exit(load_entry_point('nnunet', 'console_scripts', 'nnUNet_train')())
  File "/home/smaijer/experiment/nnUNet/nnunet/run/run_training.py", line 180, in main
    trainer.run_training()
  File "/home/smaijer/experiment/nnUNet/nnunet/training/network_training/nnUNetTrainerV2.py", line 448, in run_training
    ret = super().run_training()
  File "/home/smaijer/experiment/nnUNet/nnunet/training/network_training/nnUNetTrainer.py", line 318, in run_training
    super(nnUNetTrainer, self).run_training()
  File "/home/smaijer/experiment/nnUNet/nnunet/training/network_training/network_trainer.py", line 459, in run_training
    l = self.run_iteration(self.tr_gen, True)
  File "/home/smaijer/experiment/nnUNet/nnunet/training/network_training/nnUNetTrainerV2.py", line 253, in run_iteration
    output = self.network(data)
  File "/home/smaijer/.conda/envs/nn/lib/python3.9/site-packages/torch/nn/modules/module.py", line 1110, in _call_impl
    return forward_call(*input, **kwargs)
  File "/home/smaijer/experiment/nnUNet/nnunet/network_architecture/generic_UNet.py", line 423, in forward
    print(f"Final shape seg_outputs (pre deep supervision) {seg_outputs.shape}")
AttributeError: 'list' object has no attribute 'shape'
Exception in thread Thread-4:
Traceback (most recent call last):
  File "/home/smaijer/.conda/envs/nn/lib/python3.9/threading.py", line 973, in _bootstrap_inner
Exception in thread Thread-5:
Traceback (most recent call last):
  File "/home/smaijer/.conda/envs/nn/lib/python3.9/threading.py", line 973, in _bootstrap_inner
